Workbook

Sheet Constants
A1: Mass | B1: 0.93827231 | C1: [GeV/c^2] | I1: Type | J1: LTF | K1: Units | L1: Alternate Name
A2: Kinetic | B2: =B3-B1 -> 119.0654 | C2: [GeV] | I2: [] | J2: (calculated)
A3: E_Tot | B3: =SQRT(B1^2+B4^2) -> 120.00367 | C3: [GeV] | I3: 3-Way | J3: =(4*PI()*0.0000001*16*3.0795)/(2*0.01575) -> 0.0019656197 | K3: [T*m/A]
A4: momentum | B4: 120 | C4: [GeV/c] | I4: ADB | J4: =(4*PI()*0.0000001*68*3.048)/(2*0.028955) -> 0.0044975932 | K4: [T*m/A] | L4: 10' Wide Gap Mod. B1
I5: EDA | J5: =(4*PI()*0.0000001*410*3.1369)/(2*0.04445) -> 0.018179948 | K5: [T*m/A] | L5: 3D120
A6: c | B6: 299792458 | C6: [m/s] | I6: EDB | J6: =(4*PI()*0.0000001*32*3.0226)/(2*0.01905) -> 0.0031901826 | K6: [T*m/A] | L6: 2-Terminal EPB (5-1.5-120)
A7: k_c | B7: =1000000000/B6 -> 3.335641 | I7: EDBB | J7: =(4*PI()*0.0000001*32*3.0226)/(2*0.01905) -> 0.0031901826 | K7: [T*m/A] | L7: 4-Terminal EPB (5-1.5-120)
I8: EDBC | J8: =(4*PI()*0.0000001*32*3.0226)/(2*0.01905) -> 0.0031901826 | K8: [T*m/A] | L8: 4-Terminal EPB w/ PEEK Insulation
A9: p*k_c | B9: =B4*B7 -> 400.27691 | I9: EDE | J9: =(4*PI()*0.0000001*280*1.5971)/(2*0.036525) -> 0.0076927175 | K9: [T*m/A] | L9: Eartly (5.5-2.28-60)
I10: TDTA | J10: =(4*PI()*0.0000001*224*0.826)/(2*0.05588) -> 0.0020804225 | K10: [T*m/A] | L10: 4-4-30 Mark I
I11: TDTB | J11: =(4*PI()*0.0000001*224*0.826)/(2*0.05588) -> 0.0020804225 | K11: [T*m/A] | L11: 4-4-30 Mark II
I12: TDTC | J12: =(4*PI()*0.0000001*224*0.876)/(2*0.59855) -> 0.00020598308 | K12: [T*m/A] | L12: 4-4-30 Mark III
I13: TDTD | J13: =(4*PI()*0.0000001*224*0.8305)/(2*0.0635) -> 0.0018407457 | K13: [T*m/A] | L13: 4-4-30 Mark IV
I14: SDFB | J14: =(4*PI()*0.0000001*108*3.138)/(2*0.040386) -> 0.0052726109 | K14: [T*m/A] | L14: 6-3-120
I15: QQM | J15: =(4*PI()*0.0000001*236*3.028)/(0.0381^2) -> 0.61862546 | K15: [(T/m)*m] | L15: QQB/3Q120M | N15: QQM | O15: =(4*PI()*0.0000001*236*3.0286)/(0.0381^2)/3.048 -> 0.20300132 | P15: [T/m/A] | Q15: QQB/3Q120M
I16: QQP | J16: =(4*PI()*0.0000001*236*3.028)/(0.0381^2) -> 0.61862546 | K16: [(T/m)*m] | L16: 3Q120 | N16: QQP | O16: =(4*PI()*0.0000001*236*3.0286)/(0.0381^2)/3.048 -> 0.20300132 | P16: [T/m/A] | Q16: 3Q120
I17: RQB | J17: =0.01842553191*3.048 -> 0.056161021 | K17: [(T/m)*m] | L17: 4Q120
I18: QQK | J18: =(4*PI()*0.0000001*56*3.028)/(0.0381^2) -> 0.14679248 | K18: [(T/m)*m] | L18: 3Q120A (1980)

Sheet Geometry
A1: Path | B1: Station | C1: Name | D1: Element | E1: Type | F1: X | G1: Y | H1: Z | I1: Roll | K1: dstation | L1: station
A2: [m] | B2: [U/C/D] | C2: [] | D2: [] | E2: [] | F2: [m] | G2: [m] | H2: [m] | I2: [deg.] | K2: [m] | L2: [m]
A3: 0 | B3: U | C3: WALL0 | D3: MARKER | E3: NULL | F3: 0 | G3: 0 | H3: 0 | I3: 0 | K3: 0 | L3: 0
A4: 0 | B4: C | C4: WALL0 | D4: MARKER | E4: NULL | F4: 0 | G4: 0 | H4: 0 | I4: 0 | L4: =(L3+L5)/2 -> 0
A5: 0 | B5: D | C5: WALL0 | D5: MARKER | E5: NULL | F5: 0 | G5: 0 | H5: 0 | I5: 0 | K5: =SQRT((F5-F3)^2+(H5-H3)^2) -> 0 | L5: =L3+K5 -> 0
A7: 0.61 | B7: U | C7: M01BV1 | D7: MARKER | E7: BV | F7: 0 | G7: 0 | H7: 0.6096 | I7: 0 | K7: =SQRT((F7-F5)^2+(H7-H5)^2) -> 0.6096 | L7: =L5+K7 -> 0.6096
A8: 0.61 | B8: C | C8: M01BV1 | D8: MARKER | E8: BV | F8: 0 | G8: 0 | H8: 0.6096 | I8: 0 | L8: =(L7+L9)/2 -> 0.6096
A9: 0.61 | B9: D | C9: M01BV1 | D9: MARKER | E9: BV | F9: 0 | G9: 0 | H9: 0.6096 | I9: 0 | K9: =SQRT((F9-F7)^2+(H9-H7)^2) -> 0 | L9: =L7+K9 -> 0.6096
A11: 0.914 | B11: U | C11: M01PG1 | D11: MARKER | E11: PG | F11: 0 | G11: 0 | H11: 0.9144 | I11: 0 | K11: =SQRT((F11-F9)^2+(H11-H9)^2) -> 0.3048 | L11: =L9+K11 -> 0.9144
A12: 0.914 | B12: C | C12: M01PG1 | D12: MARKER | E12: PG | F12: 0 | G12: 0 | H12: 0.9144 | I12: 0 | L12: =(L11+L13)/2 -> 0.9144
A13: 0.914 | B13: D | C13: M01PG1 | D13: MARKER | E13: PG | F13: 0 | G13: 0 | H13: 0.9144 | I13: 0 | K13: =SQRT((F13-F11)^2+(H13-H11)^2) -> 0 | L13: =L11+K13 -> 0.9144
A15: 1.219 | B15: U | C15: M01BV2 | D15: MARKER | E15: BV | F15: 0 | G15: 0 | H15: 1.2192 | I15: 0 | K15: =SQRT((F15-F13)^2+(H15-H13)^2) -> 0.3048 | L15: =L13+K15 -> 1.2192
A16: 1.219 | B16: C | C16: M01BV2 | D16: MARKER | E16: BV | F16: 0 | G16: 0 | H16: 1.2192 | I16: 0 | L16: =(L15+L17)/2 -> 1.2192
A17: 1.219 | B17: D | C17: M01BV2 | D17: MARKER | E17: BV | F17: 0 | G17: 0 | H17: 1.2192 | I17: 0 | K17: =SQRT((F17-F15)^2+(H17-H15)^2) -> 0 | L17: =L15+K17 -> 1.2192
A19: 3.657 | B19: U | C19: M01LBP | D19: MARKER | E19: LM | F19: 0 | G19: 0 | H19: 3.6572 | I19: 0 | K19: =SQRT((F19-F17)^2+(H19-H17)^2) -> 2.438 | L19: =L17+K19 -> 3.6572
A20: 3.657 | B20: C | C20: M01LBP | D20: MARKER | E20: LM | F20: 0 | G20: 0 | H20: 3.6572 | I20: 0 | L20: =(L19+L21)/2 -> 3.6572
A21: 3.657 | B21: D | C21: M01LBP | D21: MARKER | E21: LM | F21: 0 | G21: 0 | H21: 3.6572 | I21: 0 | K21: =SQRT((F21-F19)^2+(H21-H19)^2) -> 0 | L21: =L19+K21 -> 3.6572
A23: 3.657 | B23: U | C23: M01WC1 | D23: MARKER | E23: SWIC | F23: 0 | G23: 0 | H23: 3.6572 | I23: 0 | K23: =SQRT((F23-F21)^2+(H23-H21)^2) -> 0 | L23: =L21+K23 -> 3.6572
A24: 3.657 | B24: C | C24: M01WC1 | D24: MARKER | E24: SWIC | F24: 0 | G24: 0 | H24: 3.6572 | I24: 0 | L24: =(L23+L25)/2 -> 3.6572
A25: 3.657 | B25: D | C25: M01WC1 | D25: MARKER | E25: SWIC | F25: 0 | G25: 0 | H25: 3.6572 | I25: 0 | K25: =SQRT((F25-F23)^2+(H25-H23)^2) -> 0 | L25: =L23+K25 -> 3.6572
A27: 3.911 | B27: U | C27: M01LD1 | D27: MARKER | E27: LM | F27: 0 | G27: 0 | H27: 3.9112 | I27: 0 | K27: =SQRT((F27-F25)^2+(H27-H25)^2) -> 0.254 | L27: =L25+K27 -> 3.9112
A28: 3.911 | B28: C | C28: M01LD1 | D28: MARKER | E28: LM | F28: 0 | G28: 0 | H28: 3.9112 | I28: 0 | L28: =(L27+L29)/2 -> 3.9112
A29: 3.911 | B29: D | C29: M01LD1 | D29: MARKER | E29: LM | F29: 0 | G29: 0 | H29: 3.9112 | I29: 0 | K29: =SQRT((F29-F27)^2+(H29-H27)^2) -> 0 | L29: =L27+K29 -> 3.9112
A31: 3.911 | B31: U | C31: M01D-1 | D31: RBEND | E31: ADB | F31: 0 | G31: 0 | H31: 3.9112 | I31: -90 | K31: =SQRT((F31-F29)^2+(H31-H29)^2) -> 0 | L31: =L29+K31 -> 3.9112
A32: 5.435 | B32: C | C32: M01D-1 | D32: RBEND | E32: ADB | F32: 0 | G32: 0 | H32: 5.4352 | I32: -90 | L32: =(L31+L33)/2 -> 5.4352
A33: 6.959 | B33: D | C33: M01D-1 | D33: RBEND | E33: ADB | F33: 0 | G33: 0 | H33: 6.9592 | I33: -90 | K33: =SQRT((F33-F31)^2+(H33-H31)^2) -> 3.048 | L33: =L31+K33 -> 6.9592
A35: 7.061 | B35: U | C35: M01D-2 | D35: RBEND | E35: ADB | F35: 0 | G35: 0 | H35: 7.0608 | I35: -90 | K35: =SQRT((F35-F33)^2+(H35-H33)^2) -> 0.1016 | L35: =L33+K35 -> 7.0608
A36: 8.585 | B36: C | C36: M01D-2 | D36: RBEND | E36: ADB | F36: 0 | G36: 0 | H36: 8.5848 | I36: -90 | L36: =(L35+L37)/2 -> 8.5848
A37: 10.109 | B37: D | C37: M01D-2 | D37: RBEND | E37: ADB | F37: 0 | G37: 0 | H37: 10.1088 | I37: -90 | K37: =SQRT((F37-F35)^2+(H37-H35)^2) -> 3.048 | L37: =L35+K37 -> 10.1088
A39: 10.21 | B39: U | C39: M01D-3 | D39: RBEND | E39: ADB | F39: 0 | G39: 0 | H39: 10.2104 | I39: -90 | K39: =SQRT((F39-F37)^2+(H39-H37)^2) -> 0.1016 | L39: =L37+K39 -> 10.2104
A40: 11.734 | B40: C | C40: M01D-3 | D40: RBEND | E40: ADB | F40: 0 | G40: 0 | H40: 11.7344 | I40: -90 | L40: =(L39+L41)/2 -> 11.7344
A41: 13.258 | B41: D | C41: M01D-3 | D41: RBEND | E41: ADB | F41: 0 | G41: 0 | H41: 13.2584 | I41: -90 | K41: =SQRT((F41-F39)^2+(H41-H39)^2) -> 3.048 | L41: =L39+K41 -> 13.2584
A43: 13.36 | B43: U | C43: M01D-4 | D43: RBEND | E43: ADB | F43: 0 | G43: 0 | H43: 13.36 | I43: -90 | K43: =SQRT((F43-F41)^2+(H43-H41)^2) -> 0.1016 | L43: =L41+K43 -> 13.36
A44: 14.884 | B44: C | C44: M01D-4 | D44: RBEND | E44: ADB | F44: 0 | G44: 0 | H44: 14.884 | I44: -90 | L44: =(L43+L45)/2 -> 14.884
A45: 16.408 | B45: D | C45: M01D-4 | D45: RBEND | E45: ADB | F45: 0 | G45: 0 | H45: 16.408 | I45: -90 | K45: =SQRT((F45-F43)^2+(H45-H43)^2) -> 3.048 | L45: =L43+K45 -> 16.408
A47: 16.51 | B47: U | C47: M01D-5 | D47: RBEND | E47: ADB | F47: 0 | G47: 0 | H47: 16.5096 | I47: -90 | K47: =SQRT((F47-F45)^2+(H47-H45)^2) -> 0.1016 | L47: =L45+K47 -> 16.5096
A48: 18.034 | B48: C | C48: M01D-5 | D48: RBEND | E48: ADB | F48: 0 | G48: 0 | H48: 18.0336 | I48: -90 | L48: =(L47+L49)/2 -> 18.0336
A49: 19.558 | B49: D | C49: M01D-5 | D49: RBEND | E49: ADB | F49: 0 | G49: 0 | H49: 19.5576 | I49: -90 | K49: =SQRT((F49-F47)^2+(H49-H47)^2) -> 3.048 | L49: =L47+K49 -> 19.5576
A51: 19.659 | B51: U | C51: M01PG2 | D51: MARKER | E51: PG | F51: 0 | G51: 0 | H51: 19.6591 | I51: 0 | K51: =SQRT((F51-F49)^2+(H51-H49)^2) -> 0.1015 | L51: =L49+K51 -> 19.6591
A52: 19.659 | B52: C | C52: M01PG2 | D52: MARKER | E52: PG | F52: 0 | G52: 0 | H52: 19.6591 | I52: 0 | L52: =(L51+L53)/2 -> 19.6591
...

Sheet Magnets - Fields
A1: Name | B1: Elememt | C1: Type | D1: Length | E1: bangle | F1: K1 | H1: B*s | I1: ρ | J1: s | K1: B | M1: B
A2: [] | B2: [] | C2: [] | D2: [m] | E2: [mRadian] | F2: [m^(-2)] | H2: [T*m] | I2: [m] | J2: [m] | K2: [T] | M2: [(T/m)*m]
A3: M01D-1 | B3: RBEND | C3: ADB | D3: 3.048 | E3: 0 | F3: 0 | H3: =E3*Constants!$B$9/1000 -> 0 | I3: =IF(E3=0,0,D3/(2*SIN(E3/2000))) -> 0 | J3: =I3*E3/1000 -> 0 | K3: =IF(J3=0,0,H3/J3) -> 0 | M3: =ABS(F3)*D3*Constants!$B$9 -> 0
A4: M01D-2 | B4: RBEND | C4: ADB | D4: 3.048 | E4: 0 | F4: 0 | H4: =E4*Constants!$B$9/1000 -> 0 | I4: =IF(E4=0,0,D4/(2*SIN(E4/2000))) -> 0 | J4: =I4*E4/1000 -> 0 | K4: =IF(J4=0,0,H4/J4) -> 0 | M4: =ABS(F4)*D4*Constants!$B$9 -> 0
A5: M01D-3 | B5: RBEND | C5: ADB | D5: 3.048 | E5: 0 | F5: 0 | H5: =E5*Constants!$B$9/1000 -> 0 | I5: =IF(E5=0,0,D5/(2*SIN(E5/2000))) -> 0 | J5: =I5*E5/1000 -> 0 | K5: =IF(J5=0,0,H5/J5) -> 0 | M5: =ABS(F5)*D5*Constants!$B$9 -> 0
A6: M01D-4 | B6: RBEND | C6: ADB | D6: 3.048 | E6: 0 | F6: 0 | H6: =E6*Constants!$B$9/1000 -> 0 | I6: =IF(E6=0,0,D6/(2*SIN(E6/2000))) -> 0 | J6: =I6*E6/1000 -> 0 | K6: =IF(J6=0,0,H6/J6) -> 0 | M6: =ABS(F6)*D6*Constants!$B$9 -> 0
A7: M01D-5 | B7: RBEND | C7: ADB | D7: 3.048 | E7: 0 | F7: 0 | H7: =E7*Constants!$B$9/1000 -> 0 | I7: =IF(E7=0,0,D7/(2*SIN(E7/2000))) -> 0 | J7: =I7*E7/1000 -> 0 | K7: =IF(J7=0,0,H7/J7) -> 0 | M7: =ABS(F7)*D7*Constants!$B$9 -> 0
A8: M01D-6 | B8: RBEND | C8: ADB | D8: 3.048 | E8: 0 | F8: 0 | H8: =E8*Constants!$B$9/1000 -> 0 | I8: =IF(E8=0,0,D8/(2*SIN(E8/2000))) -> 0 | J8: =I8*E8/1000 -> 0 | K8: =IF(J8=0,0,H8/J8) -> 0 | M8: =ABS(F8)*D8*Constants!$B$9 -> 0
A9: M01D-7 | B9: RBEND | C9: ADB | D9: 3.048 | E9: 0 | F9: 0 | H9: =E9*Constants!$B$9/1000 -> 0 | I9: =IF(E9=0,0,D9/(2*SIN(E9/2000))) -> 0 | J9: =I9*E9/1000 -> 0 | K9: =IF(J9=0,0,H9/J9) -> 0 | M9: =ABS(F9)*D9*Constants!$B$9 -> 0
A10: MW1W-1 | B10: RBEND | C10: 3WLam | D10: 3.048 | E10: 0.61667 | F10: 0 | H10: =E10*Constants!$B$9/1000 -> 0.24683876 | I10: =IF(E10=0,0,D10/(2*SIN(E10/2000))) -> 4942.6761 | J10: =I10*E10/1000 -> 3.048 | K10: =IF(J10=0,0,H10/J10) -> 0.080983845 | M10: =ABS(F10)*D10*Constants!$B$9 -> 0
A11: MW1W-2 | B11: RBEND | C11: 3WLam | D11: 3.048 | E11: 0.61667 | F11: 0 | H11: =E11*Constants!$B$9/1000 -> 0.24683876 | I11: =IF(E11=0,0,D11/(2*SIN(E11/2000))) -> 4942.6761 | J11: =I11*E11/1000 -> 3.048 | K11: =IF(J11=0,0,H11/J11) -> 0.080983845 | M11: =ABS(F11)*D11*Constants!$B$9 -> 0
A12: MW1W-3 | B12: RBEND | C12: 3WLam | D12: 3.048 | E12: 0.61667 | F12: 0 | H12: =E12*Constants!$B$9/1000 -> 0.24683876 | I12: =IF(E12=0,0,D12/(2*SIN(E12/2000))) -> 4942.6761 | J12: =I12*E12/1000 -> 3.048 | K12: =IF(J12=0,0,H12/J12) -> 0.080983845 | M12: =ABS(F12)*D12*Constants!$B$9 -> 0
A13: MW1W-4 | B13: RBEND | C13: 3WLam | D13: 3.048 | E13: 0.61667 | F13: 0 | H13: =E13*Constants!$B$9/1000 -> 0.24683876 | I13: =IF(E13=0,0,D13/(2*SIN(E13/2000))) -> 4942.6761 | J13: =I13*E13/1000 -> 3.048 | K13: =IF(J13=0,0,H13/J13) -> 0.080983845 | M13: =ABS(F13)*D13*Constants!$B$9 -> 0
A14: MW1W-5 | B14: RBEND | C14: 3WLam | D14: 3.048 | E14: 0.61667 | F14: 0 | H14: =E14*Constants!$B$9/1000 -> 0.24683876 | I14: =IF(E14=0,0,D14/(2*SIN(E14/2000))) -> 4942.6761 | J14: =I14*E14/1000 -> 3.048 | K14: =IF(J14=0,0,H14/J14) -> 0.080983845 | M14: =ABS(F14)*D14*Constants!$B$9 -> 0
... A56: MT5HT2 | B56: HKICK | C56: TDTA | D56: 0.762 | E56: 0 | F56: 0 | H56: =E56*Constants!$B$9/1000 -> 0 | I56: =IF(E56=0,0,D56/(2*SIN(E56/2000))) -> 0 | J56: =I56*E56/1000 -> 0 | K56: =IF(J56=0,0,H56/J56) -> 0 | M56: =ABS(F56)*D56*Constants!$B$9 -> 0

Sheet Magnets - Currents
A1: Name | B1: Element | C1: Type | E1: B*s | F1: B | H1: LTF | J1: I
A2: [] | B2: [] | C2: [] | E2: [T*m] | F2: [T] | H2: (calculated) | J2: [amp]
A3: M01D-1 | B3: RBEND | C3: ADB | E3: ='Magnets - Fields'!H3 -> 0 | F3: ='Magnets - Fields'!M3 -> 0 | H3: =Constants!$J$4 -> 0.0044975932 | J3: =IF(B3="QUAD",(F3/H3),(E3/H3)) -> 0
A4: M01D-2 | B4: RBEND | C4: ADB | E4: ='Magnets - Fields'!H4 -> 0 | F4: ='Magnets - Fields'!M4 -> 0 | H4: =Constants!$J$4 -> 0.0044975932 | J4: =IF(B4="QUAD",(F4/H4),(E4/H4)) -> 0
A5: M01D-3 | B5: RBEND | C5: ADB | E5: ='Magnets - Fields'!H5 -> 0 | F5: ='Magnets - Fields'!M5 -> 0 | H5: =Constants!$J$4 -> 0.0044975932 | J5: =IF(B5="QUAD",(F5/H5),(E5/H5)) -> 0
A6: M01D-4 | B6: RBEND | C6: ADB | E6: ='Magnets - Fields'!H6 -> 0 | F6: ='Magnets - Fields'!M6 -> 0 | H6: =Constants!$J$4 -> 0.0044975932 | J6: =IF(B6="QUAD",(F6/H6),(E6/H6)) -> 0
A7: M01D-5 | B7: RBEND | C7: ADB | E7: ='Magnets - Fields'!H7 -> 0 | F7: ='Magnets - Fields'!M7 -> 0 | H7: =Constants!$J$4 -> 0.0044975932 | J7: =IF(B7="QUAD",(F7/H7),(E7/H7)) -> 0
A8: M01D-6 | B8: RBEND | C8: ADB | E8: ='Magnets - Fields'!H8 -> 0 | F8: ='Magnets - Fields'!M8 -> 0 | H8: =Constants!$J$4 -> 0.0044975932 | J8: =IF(B8="QUAD",(F8/H8),(E8/H8)) -> 0
A9: M01D-7 | B9: RBEND | C9: ADB | E9: ='Magnets - Fields'!H9 -> 0 | F9: ='Magnets - Fields'!M9 -> 0 | H9: =Constants!$J$4 -> 0.0044975932 | J9: =IF(B9="QUAD",(F9/H9),(E9/H9)) -> 0
A10: MW1W-1 | B10: RBEND | C10: 3WLam | E10: ='Magnets - Fields'!H10 -> 0.24683876 | F10: ='Magnets - Fields'!M10 -> 0 | H10: =Constants!$J$3 -> 0.0019656197 | J10: =IF(B10="QUAD",(F10/H10),(E10/H10)) -> 125.57809
A11: MW1W-2 | B11: RBEND | C11: 3WLam | E11: ='Magnets - Fields'!H11 -> 0.24683876 | F11: ='Magnets - Fields'!M11 -> 0 | H11: =Constants!$J$3 -> 0.0019656197 | J11: =IF(B11="QUAD",(F11/H11),(E11/H11)) -> 125.57809
A12: MW1W-3 | B12: RBEND | C12: 3WLam | E12: ='Magnets - Fields'!H12 -> 0.24683876 | F12: ='Magnets - Fields'!M12 -> 0 | H12: =Constants!$J$3 -> 0.0019656197 | J12: =IF(B12="QUAD",(F12/H12),(E12/H12)) -> 125.57809
A13: MW1W-4 | B13: RBEND | C13: 3WLam | E13: ='Magnets - Fields'!H13 -> 0.24683876 | F13: ='Magnets - Fields'!M13 -> 0 | H13: =Constants!$J$3 -> 0.0019656197 | J13: =IF(B13="QUAD",(F13/H13),(E13/H13)) -> 125.57809
A14: MW1W-5 | B14: RBEND | C14: 3WLam | E14: ='Magnets - Fields'!H14 -> 0.24683876 | F14: ='Magnets - Fields'!M14 -> 0 | H14: =Constants!$J$3 -> 0.0019656197 | J14: =IF(B14="QUAD",(F14/H14),(E14/H14)) -> 125.57809
A15: MW1W-6 | B15: RBEND | C15: 3WLam | E15: ='Magnets - Fields'!H15 -> 0.24683876 | F15: ='Magnets - Fields'!M15 -> 0 | H15: =Constants!$J$3 -> 0.0019656197 | J15: =IF(B15="QUAD",(F15/H15),(E15/H15)) -> 125.57809
A16: MT2Q1 | B16: QUAD | C16: QQP | E16: ='Magnets - Fields'!H16 -> 0 | F16: ='Magnets - Fields'!M16 -> 0 | H16: =Constants!$J$16 -> 0.61862546 | J16: =IF(B16="QUAD",(F16/H16),(E16/H16)) -> 0
A17: MT2Q2 | B17: QUAD | C17: QQP | E17: ='Magnets - Fields'!H17 -> 0 | F17: ='Magnets - Fields'!M17 -> 0 | H17: =Constants!$J$16 -> 0.61862546 | J17: =IF(B17="QUAD",(F17/H17),(E17/H17)) -> 0
A18: MT2WD1-1 | B18: RBEND | C18: EPB | E18: ='Magnets - Fields'!H18 -> -3.1664786 | F18: ='Magnets - Fields'!M18 -> 0 | H18: =Constants!$J$6 -> 0.0031901826 | J18: =IF(B18="QUAD",(F18/H18),(E18/H18)) -> -992.5697
A19: MT2WD1-2 | B19: RBEND | C19: EPB | E19: ='Magnets - Fields'!H19 -> -3.1664786 | F19: ='Magnets - Fields'!M19 -> 0 | H19: =Constants!$J$6 -> 0.0031901826 | J19: =IF(B19="QUAD",(F19/H19),(E19/H19)) -> -992.5697
A20: MT2WD2-1 | B20: RBEND | C20: SDF | E20: ='Magnets - Fields'!H20 -> -2.0072126 | F20: ='Magnets - Fields'!M20 -> 0 | H20: =Constants!$J$14 -> 0.0052726109 | J20: =IF(B20="QUAD",(F20/H20),(E20/H20)) -> -380.68666
A21: MT2WD2-2 | B21: RBEND | C21: SDF | E21: ='Magnets - Fields'!H21 -> -2.0072126 | F21: ='Magnets - Fields'!M21 -> 0 | H21: =Constants!$J$14 -> 0.0052726109 | J21: =IF(B21="QUAD",(F21/H21),(E21/H21)) -> -380.68666
A22: MT2WD2-3 | B22: RBEND | C22: SDF | E22: ='Magnets - Fields'!H22 -> -2.0072126 | F22: ='Magnets - Fields'!M22 -> 0 | H22: =Constants!$J$14 -> 0.0052726109 | J22: =IF(B22="QUAD",(F22/H22),(E22/H22)) -> -380.68666
A23: MT2V | B23: RBEND | C23: TDTA | E23: ='Magnets - Fields'!H23 -> 0 | F23: ='Magnets - Fields'!M23 -> 0 | H23: =Constants!$J$10 -> 0.0020804225 | J23: =IF(B23="QUAD",(F23/H23),(E23/H23)) -> 0
A24: MT2WU-1 | B24: RBEND | C24: EPB | E24: ='Magnets - Fields'!H24 -> -2.2918095 | F24: ='Magnets - Fields'!M24 -> 0 | H24: =Constants!$J$6 -> 0.0031901826 | J24: =IF(B24="QUAD",(F24/H24),(E24/H24)) -> -718.39445
A25: MT2WU-2 | B25: RBEND | C25: EPB | E25: ='Magnets - Fields'!H25 -> -2.2918095 | F25: ='Magnets - Fields'!M25 -> 0 | H25: =Constants!$J$6 -> 0.0031901826 | J25: =IF(B25="QUAD",(F25/H25),(E25/H25)) -> -718.39445
A26: MT2WU-3 | B26: RBEND | C26: EPB | E26: ='Magnets - Fields'!H26 -> -2.2918095 | F26: ='Magnets - Fields'!M26 -> 0 | H26: =Constants!$J$6 -> 0.0031901826 | J26: =IF(B26="QUAD",(F26/H26),(E26/H26)) -> -718.39445
A27: MT2WU-4 | B27: RBEND | C27: EPB | E27: ='Magnets - Fields'!H27 -> -2.2918095 | F27: ='Magnets - Fields'!M27 -> 0 | H27: =Constants!$J$6 -> 0.0031901826 | J27: =IF(B27="QUAD",(F27/H27),(E27/H27)) -> -718.39445
A28: MT2WU-5 | B28: RBEND | C28: EPB | E28: ='Magnets - Fields'!H28 -> -2.2918095 | F28: ='Magnets - Fields'!M28 -> 0 | H28: =Constants!$J$6 -> 0.0031901826 | J28: =IF(B28="QUAD",(F28/H28),(E28/H28)) -> -718.39445
A29: MT3Q1 | B29: QUAD | C29: QQB | E29: ='Magnets - Fields'!H29 -> 0 | F29: ='Magnets - Fields'!M29 -> 0 | H29: =Constants!$J$15 -> 0.61862546 | J29: =IF(B29="QUAD",(F29/H29),(E29/H29)) -> 0
A30: MT3Q2 | B30: QUAD | C30: QQB | E30: ='Magnets - Fields'!H30 -> 0 | F30: ='Magnets - Fields'!M30 -> 0 | H30: =Constants!$J$15 -> 0.61862546 | J30: =IF(B30="QUAD",(F30/H30),(E30/H30)) -> 0
A31: MT3V | B31: VKICK | C31: TDTD | E31: ='Magnets - Fields'!H31 -> 0 | F31: ='Magnets - Fields'!M31 -> 0 | H31: =Constants!$J$13 -> 0.0018407457 | J31: =IF(B31="QUAD",(F31/H31),(E31/H31)) -> 0
A32: MT3Q3 | B32: QUAD | C32: QQB | E32: ='Magnets - Fields'!H32 -> 0 | F32: ='Magnets - Fields'!M32 -> 0 | H32: =Constants!$J$15 -> 0.61862546 | J32: =IF(B32="QUAD",(F32/H32),(E32/H32)) -> 0
A33: MT3Q4 | B33: QUAD | C33: QQB | E33: ='Magnets - Fields'!H33 -> 0 | F33: ='Magnets - Fields'!M33 -> 0 | H33: =Constants!$J$15 -> 0.61862546 | J33: =IF(B33="QUAD",(F33/H33),(E33/H33)) -> 0
A34: MT3W | B34: RBEND | C34: EPB | E34: ='Magnets - Fields'!H34 -> -2.5377556 | F34: ='Magnets - Fields'!M34 -> 0 | H34: =Constants!$J$6 -> 0.0031901826 | J34: =IF(B34="QUAD",(F34/H34),(E34/H34)) -> -795.48914
A35: MT3U-1 | B35: RBEND | C35: EDA | E35: ='Magnets - Fields'!H35 -> 0.64104748 | F35: ='Magnets - Fields'!M35 -> 0 | H35: =Constants!$J$5 -> 0.018179948 | J35: =IF(B35="QUAD",(F35/H35),(E35/H35)) -> 35.261239
A36: MT3U-2 | B36: RBEND | C36: EDA | E36: ='Magnets - Fields'!H36 -> 0.64104748 | F36: ='Magnets - Fields'!M36 -> 0 | H36: =Constants!$J$5 -> 0.018179948 | J36: =IF(B36="QUAD",(F36/H36),(E36/H36)) -> 35.261239
A37: MT4Q1 | B37: QUAD | C37: QQP | E37: ='Magnets - Fields'!H37 -> 0 | F37: ='Magnets - Fields'!M37 -> 0 | H37: =Constants!$J$16 -> 0.61862546 | J37: =IF(B37="QUAD",(F37/H37),(E37/H37)) -> 0
A38: MT4W-1 | B38: RBEND | C38: EPB | E38: ='Magnets - Fields'!H38 -> -3.2020152 | F38: ='Magnets - Fields'!M38 -> 0 | H38: =Constants!$J$6 -> 0.0031901826 | J38: =IF(B38="QUAD",(F38/H38),(E38/H38)) -> -1003.7091
A39: MT4Q2 | B39: QUAD | C39: QQP | E39: ='Magnets - Fields'!H39 -> 0 | F39: ='Magnets - Fields'!M39 -> 0 | H39: =Constants!$J$16 -> 0.61862546 | J39: =IF(B39="QUAD",(F39/H39),(E39/H39)) -> 0
A40: MT4W-2 | B40: RBEND | C40: EPB | E40: ='Magnets - Fields'!H40 -> -3.2020152 | F40: ='Magnets - Fields'!M40 -> 0 | H40: =Constants!$J$6 -> 0.0031901826 | J40: =IF(B40="QUAD",(F40/H40),(E40/H40)) -> -1003.7091
...

Sheet Magnets - SN
A1: Path | B1: Station | C1: Name | D1: Elememt | E1: Type | F1: Serial Number | G1: Location
A2: [m] | B2: [U/C/D] | C2: [] | D2: [] | E2: [] | F2: [] | G2: []
A3: 5.435 | B3: C | C3: M01D-1 | D3: RBEND | E3: ADB | F3: FRD11274 | G3: M01
A4: 8.585 | B4: C | C4: M01D-2 | D4: RBEND | E4: ADB | F4: FRD11937 | G4: M01
A5: 11.734 | B5: C | C5: M01D-3 | D5: RBEND | E5: ADB | F5: FRD11936 | G5: M01
A6: 14.884 | B6: C | C6: M01D-4 | D6: RBEND | E6: ADB | F6: FRD11935 | G6: M01
A7: 18.034 | B7: C | C7: M01D-5 | D7: RBEND | E7: ADB | F7: FRD11934 | G7: M01
A8: 21.183 | B8: C | C8: M01D-6 | D8: RBEND | E8: ADB | F8: FRD11275 | G8: M01
A9: 24.333 | B9: C | C9: M01D-7 | D9: RBEND | E9: ADB | F9: FRD20703 | G9: M01
A10: 27.736 | B10: C | C10: M01SHLD | D10: DRIFT | E10: 3WLam | F10: FRD10793 | G10: M01
A11: 30.861 | B11: C | C11: MW1W-1 | D11: RBEND | E11: 3WLam | F11: FRD11950 | G11: M01
A12: 34.01 | B12: C | C12: MW1W-2 | D12: RBEND | E12: 3WLam | F12: FRD11213 | G12: M01
A13: 37.16 | B13: C | C13: MW1W-3 | D13: RBEND | E13: 3WLam | F13: FRD11930 | G13: M01
A14: 40.309 | B14: C | C14: MW1W-4 | D14: RBEND | E14: 3WLam | F14: FRD11929 | G14: M01
... A58: 485.939 | B58: C | C58: MT5HT2 | D58: HKICK | E58: TDTA | F58: FRD11613 | G58: M05

Sheet Vacuum
A1: Path | B1: Name | C1: Type | D1: Valve Control | E1: Notes | G1: Devices Not in Beam Line | H1: Notes
A2: [m] | B2: [] | C2: [] | D2: [] | E2: [] | G2: [] | H2: []
A3: 0.61 | B3: M01BV1 | C3: BV | D3: Manual | G3: MT2MV1 | H3: On vacuum header split in US M02.
A4: 0.914 | B4: M01PG1 | C4: PG | D4: N/A | H4: Used to isolate MTest Vacuum from M02RP1 & MCenter Vacuum.
A5: 1.219 | B5: M01BV2 | C5: BV | D5: Manual
A6: 19.659 | B6: M01PG2 | C6: PG | D6: N/A | E6: On vacuum header from M01RP1. Not connected to beam line vacuum.
A7: 19.659 | B7: M01RP1 | C7: RP | D7: N/A | E7: Vacuum header disconnected from beam line. Pump electrically disconnected.
A8: 64.562 | B8: M01RP2 | C8: RP | D8: N/A
A9: 64.562 | B9: M01PG3 | C9: PG | D9: N/A
A10: 89.378 | B10: WINDOW | C10: WIN | D10: N/A | E10: Ti Window US MW1SEM
A11: 89.81 | B11: WINDOW | C11: WIN | D11: N/A | E11: TI Window DS MW1SEM
A12: 91.664 | B12: WINDOW | C12: WIN | D12: N/A | E12: Ti Window US M01 Target
A13: 91.969 | B13: WINDOW | C13: WIN | D13: N/A | E13: Ti Window DS M01 Target
A14: 118.729 | B14: M02PG1 | C14: PG | D14: N/A
A15: 177.079 | B15: MT2PG1 | C15: PG | D15: N/A
A16: 177.727 | B16: MT2BV1 | C16: BV | D16: Manual
A17: 236.915 | B17: M02RP2 | C17: RP | D17: N/A | E17: Electrical Issues found during Shutdown 2022
A18: 237.173 | B18: MT2PG2 | C18: PG | D18: N/A
A19: 237.262 | B19: MT2BV2 | C19: BV | D19: Manual
A20: 238.38 | B20: MT2BV3 | C20: BV | D20: Manual
A21: 238.52 | B21: MT2PG3 | C21: PG | D21: N/A
A22: 277.621 | B22: M03BV1 | C22: BV | D22: Manual
A23: 281.278 | B23: WINDOW | C23: WIN | D23: N/A | E23: Ti Window US M03 High-Rate Tracking Area
A24: 282.802 | B24: WINDOW | C24: WIN | D24: N/A | E24: Ti Window DS M03 High-Rate Tracking Area
A25: 286.72 | B25: MT3PG1 | C25: PG | D25: N/A
A26: 288.142 | B26: WINDOW | C26: WIN | D26: N/A | E26: Ti Window US MT3 Pinhole Collimator
A27: 291.292 | B27: WINDOW | C27: WIN | D27: N/A | E27: Ti Window DS MT3 Pinhole Collimator
A28: 291.698 | B28: MT3BV2 | C28: BV | D28: Manual
A29: 333.029 | B29: MT3PG2 | C29: PG | D29: N/A
A30: 333.118 | B30: MT3BV3 | C30: BV | D30: Manual
A31: 334.236 | B31: MT3BV4 | C31: BV | D31: Manual
A32: 334.376 | B32: MT3PG3 | C32: PG | D32: N/A
A33: 349.532 | B33: MT3BV5 | C33: BV | D33: Manual
A34: 351.03 | B34: MT3PG4 | C34: PG | D34: N/A | E34: On vacuum bypass next to beam pipe
A35: 351.335 | B35: WINDOW | C35: WIN | D35: N/A | E35: Ti Window US MT3PWC
A36: 352.722 | B36: WINDOW | C36: WIN | D36: N/A | E36: Ti Window DS MT3PWC
A37: 366.41 | B37: WINDOW | C37: WIN | D37: N/A | E37: Ti Window US MT3CON2
A38: 366.436 | B38: WINDOW | C38: WIN | D38: N/A | E38: Ti Window DS MT3CON2
A39: 383.757 | B39: WINDOW | C39: WIN | D39: N/A | E39: Ti Window US MT4 Target
A40: 385.821 | B40: MT4WIN | C40: WIN | D40: N/A | E40: Ti Window DS MT4 Target in Shield Pile
...

Sheet Power Supplies
A1: Name | B1: Element | C1: Type | E1: Power Supply | F1: Type | G1: Location
A2: [] | B2: [] | C2: [] | E2: [] | F2: [] | G2: []
A3: M01D-1 | B3: RBEND | C3: ADB | E3: F:M01D | F3: Transrex 500-5 | G3: MS1
A4: M01D-2 | B4: RBEND | C4: ADB | E4: F:M01D | F4: Transrex 500-5 | G4: MS1
A5: M01D-3 | B5: RBEND | C5: ADB | E5: F:M01D | F5: Transrex 500-5 | G5: MS1
A6: M01D-4 | B6: RBEND | C6: ADB | E6: F:M01D | F6: Transrex 500-5 | G6: MS1
A7: M01D-5 | B7: RBEND | C7: ADB | E7: F:M01D | F7: Transrex 500-5 | G7: MS1
A8: M01D-6 | B8: RBEND | C8: ADB | E8: F:M01D | F8: Transrex 500-5 | G8: MS1
A9: M01D-7 | B9: RBEND | C9: ADB | E9: F:M01D | F9: Transrex 500-5 | G9: MS1
A10: MW1W-1 | B10: RBEND | C10: 3WLam | E10: F:MW1W | F10: Transrex 240-1.2 | G10: MS1
A11: MW1W-2 | B11: RBEND | C11: 3WLam | E11: F:MW1W | F11: Transrex 240-1.2 | G11: MS1
A12: MW1W-3 | B12: RBEND | C12: 3WLam | E12: F:MW1W | F12: Transrex 240-1.2 | G12: MS1
... A72: MT5HT2 | B72: HKICK | C72: TDTA | E72: F:MT5HT2 | F72: P=EI 20kW | G72: MS4

Sheet Instrumentation
A1: Device | I1: Service | J1: Loss Monitor | K1: Profile Monitor | M1: Chamber | N1: Power | O1: Controller
A2: Name | B2: Element | C2: Type | D2: X | E2: Y | F2: Z | G2: Path | I2: Building | J2: Type | K2: Type | L2: Pitch | M2: Type | N2: Supply | O2: Location | P2: Notes
A3: [] | B3: [] | C3: [] | D3: [m] | E3: [m] | F3: [m] | G3: [m] | K3: (MW/SWIC/PWC) | L3: [mm]
A4: M01LBP | B4: MARKER | C4: LM | D4: 0 | E4: 0 | F4: 3.6572 | G4: 3.657 | I4: MS1 | J4: Sealed Tube | K4: N/A | L4: N/A | M4: N/A | N4: F:MS1LMHV | O4: MS1
A5: M01WC1 | B5: MARKER | C5: SWIC | D5: 0 | E5: 0 | F5: 3.6572 | G5: 3.657 | I5: MS1 | J5: N/A | K5: SWIC | L5: 2 | M5: Bayonet | N5: F:SM01HV | O5: MS1
A6: M01LD1 | B6: MARKER | C6: LM | D6: 0 | E6: 0 | F6: 3.9112 | G6: 3.911 | I6: MS1 | J6: Coax | K6: N/A | L6: N/A | M6: N/A | N6: F:MS1LMHV | O6: MS1
A7: M01LD7 | B7: MARKER | C7: LM | D7: 0 | E7: 0 | F7: 22.8087 | G7: 22.809 | I7: MS1 | J7: Coax | K7: N/A | L7: N/A | M7: N/A | N7: F:MS1LMHV | O7: MS1
A8: M01WC2 | B8: MARKER | C8: SWIC | D8: 0 | E8: 0 | F8: 25.9583 | G8: 25.958 | I8: MS1 | J8: N/A | K8: SWIC | L8: 2 | M8: Bayonet | N8: F:SM11HV | O8: MS1
A9: M01LSHDE | B9: MARKER | C9: LM | D9: 0 | E9: 0 | F9: 26.2123 | G9: 26.212 | I9: MS1 | J9: Coax | K9: N/A | L9: N/A | M9: N/A | N9: F:MS1LMHV | O9: MS1
A10: M01LSHDW | B10: MARKER | C10: LM | D10: 0 | E10: 0 | F10: 26.2123 | G10: 26.212 | I10: MS1 | J10: Coax | K10: N/A | L10: N/A | M10: N/A | N10: F:MS1LMHV | O10: MS1
A11: M01TLM1 | B11: MARKER | C11: LM | D11: 0 | E11: 0 | F11: 29.3365 | G11: 29.337 | I11: MS1 | J11: Coax | K11: N/A | L11: N/A | M11: N/A | N11: F:MS1LMHV | O11: MS1
A12: M01LB2 | B12: MARKER | C12: LM | D12: -0.0348 | E12: 0 | F12: 48.1324 | G12: 48.132 | I12: MS1 | J12: Coax | K12: N/A | L12: N/A | M12: N/A | N12: F:MS1LMHV | O12: MS1
A13: MW1SEM | B13: MARKER | C13: SEM | D13: -0.1882 | E13: 0 | F13: 89.594 | G13: 89.594 | I13: MS1 | J13: N/A | K13: N/A | L13: N/A | M13: N/A | N13: N/A | O13: MS1
A14: MW1WC1 | B14: MARKER | C14: SWIC | D14: -0.1946 | E14: 0 | F14: 91.3339 | G14: 91.334 | I14: MS1 | J14: N/A | K14: PWC | L14: 1 | M14: Fixed | N14: F:SMW1HV | O14: MS1
A15: MW1LM1 | B15: MARKER | C15: LM | D15: -0.1946 | E15: 0 | F15: 91.3339 | G15: 91.334 | I15: MS1 | J15: Coax | K15: N/A | L15: N/A | M15: N/A | N15: F:MS1LMHV | O15: MS1
A16: MW2WC | B16: MARKER | C16: SWIC | D16: 0.5757 | E16: -0.1351 | F16: 177.3723 | G16: 177.384 | I16: MS2 | J16: N/A | K16: SWIC | L16: 1 | M16: Bayonet | N16: F:MW2WCV | O16: MS2
A17: MW3PWC1 | B17: MARKER | C17: SWIC | D17: 6.1424 | E17: -0.3511 | F17: 282.9464 | G17: 283.107 | I17: MS2 | J17: N/A | K17: PWC | L17: 1 | M17: Bayonet | N17: F:MW3WCV | O17: MS2
A18: MT3PWC | B18: MARKER | C18: SWIC | D18: 9.9106 | E18: -0.4746 | F18: 351.4013 | G18: 351.665 | I18: MS3 | J18: N/A | K18: PWC | L18: 2 | M18: Fixed | N18: F:MT3PWV | O18: MS3
A19: MT4PWC | B19: MARKER | C19: SWIC | D19: 11.7893 | E19: -0.5083 | F19: 383.6797 | G19: 383.999 | I19: MS3 | J19: N/A | K19: PWC | L19: 2 | M19: Fixed | N19: F:MT4PWV | O19: MS3 | P19: Replaced Shutdown 2022
A20: MT4SEM | B20: DRIFT | C20: IC | D20: 11.8039 | E20: -0.508 | F20: 383.9174 | G20: 384.2365 | I20: MS3 | J20: N/A | K20: N/A | L20: N/A | M20: N/A | N20: F:MT4ICV | O20: MS3
A21: MT4FP | B21: MARKER | C21: SWIC | D21: 14.4251 | E21: -0.4555 | F21: 421.2611 | G21: 421.673 | I21: MS4 | J21: N/A | K21: FPM | L21: 1 | M21: Bayonet | N21: F:MT4FPV | O21: MS4
A22: MT5FP1 | B22: MARKER | C22: SWIC | D22: 16.3058 | E22: -0.4213 | F22: 445.5326 | G22: 446.017 | I22: MS4 | J22: N/A | K22: FPM | L22: 1 | M22: Bayonet | N22: F:MT5F1V | O22: M05 Enclosure | P22: Controller in Cable Tray
A23: MT5FP2 | B23: MARKER | C23: SWIC | D23: 18.1776 | E23: -0.3643 | F23: 486.2055 | G23: 486.739 | I23: MS4 | J23: N/A | K23: FPM | L23: 1 | M23: Bayonet | N23: F:MT5F2V | O23: M05 Enclosure | P23: Dead
A24: MT6SC1 | B24: MARKER | C24: SCI | D24: 19.3073 | E24: -0.3162 | F24: 520.6126 | G24: 521.165 | I24: MS4 | J24: N/A | K24: N/A | L24: N/A | M24: N/A | N24: N/A | O24: MS4
A25: MT6PWC1 | B25: MARKER | C25: SWIC | D25: 19.3083 | E25: -0.3162 | F25: 520.6431 | G25: 521.195 | I25: MS4 | J25: N/A | K25: PWC | L25: 1 | M25: Fixed | N25: F:MT6P1V | O25: MT6-1 Enclosure | P25: Controller next to chamber
A26: MT6PWC2 | B26: MARKER | C26: SWIC | D26: 19.6242 | E26: -0.3027 | F26: 530.2639 | G26: 530.821 | I26: MS4 | J26: N/A | K26: PWC | L26: 1 | M26: Fixed | N26: F:MT6P2V | O26: MT6-1 Enclosure | P26: Controller next to chamber
A27: MT6SC3 | B27: MARKER | C27: SCI | D27: 19.7959 | E27: -0.2954 | F27: 535.4935 | G27: 536.053 | I27: MS4 | J27: N/A | K27: N/A | L27: N/A | M27: N/A | N27: N/A | O27: MS4
A28: MT6PWC3 | B28: MARKER | C28: SWIC | D28: 20.1612 | E28: -0.2798 | F28: 546.6175 | G28: 547.183 | I28: MS4 | J28: N/A | K28: PWC | L28: 2 | M28: Fixed | N28: F:MT6P3V | O28: MT6-2 Enclosure | P28: Controller on roof of hut

Sheet bsheet
A1: Column1 | B1: Column2 | C1: Column3 | D1: Column4 | E1: Column5 | F1: Column6 | G1: Column7 | H1: Column8 | I1: Column9
A2: U | B2: WALL0 | C2: MARKER | D2: NULL | E2: 0 | F2: 0 | G2: 0 | H2: 0 | I2: 0
A3: C | B3: WALL0 | C3: MARKER | D3: NULL | E3: 0 | F3: 0 | G3: 0 | H3: 0 | I3: 0
A4: D | B4: WALL0 | C4: MARKER | D4: NULL | E4: 0 | F4: 0 | G4: 0 | H4: 0 | I4: 0
A6: U | B6: M01BV1 | C6: MARKER | D6: BV | E6: 0.61 | F6: 0 | G6: 0 | H6: 0.6096 | I6: 0
A7: C | B7: M01BV1 | C7: MARKER | D7: BV | E7: 0.61 | F7: 0 | G7: 0 | H7: 0.6096 | I7: 0
A8: D | B8: M01BV1 | C8: MARKER | D8: BV | E8: 0.61 | F8: 0 | G8: 0 | H8: 0.6096 | I8: 0
A10: U | B10: M01PG1 | C10: MARKER | D10: PG | E10: 0.914 | F10: 0 | G10: 0 | H10: 0.9144 | I10: 0
A11: C | B11: M01PG1 | C11: MARKER | D11: PG | E11: 0.914 | F11: 0 | G11: 0 | H11: 0.9144 | I11: 0
A12: D | B12: M01PG1 | C12: MARKER | D12: PG | E12: 0.914 | F12: 0 | G12: 0 | H12: 0.9144 | I12: 0
A14: U | B14: M01BV2 | C14: MARKER | D14: BV | E14: 1.219 | F14: 0 | G14: 0 | H14: 1.2192 | I14: 0
A15: C | B15: M01BV2 | C15: MARKER | D15: BV | E15: 1.219 | F15: 0 | G15: 0 | H15: 1.2192 | I15: 0
A16: D | B16: M01BV2 | C16: MARKER | D16: BV | E16: 1.219 | F16: 0 | G16: 0 | H16: 1.2192 | I16: 0
... A588: D | B588: MT62END | C588: MARKER | D588: NULL | E588: 559.373 | F588: 20.5612 | G588: -0.2628 | H588: 558.8009 | I588: 0

Sheet isheet
A1: Column1 | B1: Column2 | C1: Column3 | D1: Column4 | E1: Column5 | F1: Column6 | G1: Column7
A2: BEAM | B2: 0.000000
A3: BEAM | B3: 0.000000
A4: WALL0 | B4: MARKER | C4: 0 | D4: 0 | E4: 0 | F4: 0 | G4: NULL
A5: M01BV1 | B5: MARKER | C5: 0 | D5: 0 | E5: 0 | F5: 0 | G5: BV
A6: M01PG1 | B6: MARKER | C6: 0 | D6: 0 | E6: 0 | F6: 0 | G6: PG
A7: M01BV2 | B7: MARKER | C7: 0 | D7: 0 | E7: 0 | F7: 0 | G7: BV
A8: M01LBP | B8: MARKER | C8: 0 | D8: 0 | E8: 0 | F8: 0 | G8: LM
A9: M01WC1 | B9: MARKER | C9: 0 | D9: 0 | E9: 0 | F9: 0 | G9: SWIC
A10: M01LD1 | B10: MARKER | C10: 0 | D10: 0 | E10: 0 | F10: 0 | G10: LM
A11: M01D$1 | B11: RBEND | C11: 3.048 | D11: -90 | E11: 0 | F11: 0 | G11: ADB
A12: M01D$2 | B12: RBEND | C12: 3.048 | D12: -90 | E12: 0 | F12: 0 | G12: ADB
A13: M01D$3 | B13: RBEND | C13: 3.048 | D13: -90 | E13: 0 | F13: 0 | G13: ADB
A14: M01D$4 | B14: RBEND | C14: 3.048 | D14: -90 | E14: 0 | F14: 0 | G14: ADB
A15: M01D$5 | B15: RBEND | C15: 3.048 | D15: -90 | E15: 0 | F15: 0 | G15: ADB
... A150: MT62END | B150: MARKER | C150: 0 | D150: 0 | E150: 0 | F150: 0 | G150: NULL
